{"trial_id": "0254", "hyperparameters": {"space": [{"class_name": "Choice", "config": {"name": "activation", "default": "relu", "conditions": [], "values": ["relu", "tanh", "sigmoid"], "ordered": false}}, {"class_name": "Int", "config": {"name": "first_units", "default": null, "conditions": [], "min_value": 1, "max_value": 30, "step": 5, "sampling": "linear"}}, {"class_name": "Int", "config": {"name": "num_layers", "default": null, "conditions": [], "min_value": 1, "max_value": 5, "step": 1, "sampling": "linear"}}, {"class_name": "Int", "config": {"name": "units_0", "default": null, "conditions": [], "min_value": 1, "max_value": 30, "step": 5, "sampling": "linear"}}, {"class_name": "Int", "config": {"name": "units_1", "default": null, "conditions": [], "min_value": 1, "max_value": 30, "step": 5, "sampling": "linear"}}, {"class_name": "Int", "config": {"name": "units_2", "default": null, "conditions": [], "min_value": 1, "max_value": 30, "step": 5, "sampling": "linear"}}, {"class_name": "Int", "config": {"name": "units_3", "default": null, "conditions": [], "min_value": 1, "max_value": 30, "step": 5, "sampling": "linear"}}, {"class_name": "Int", "config": {"name": "units_4", "default": null, "conditions": [], "min_value": 1, "max_value": 30, "step": 5, "sampling": "linear"}}], "values": {"activation": "tanh", "first_units": 16, "num_layers": 2, "units_0": 6, "units_1": 1, "units_2": 11, "units_3": 11, "units_4": 21, "tuner/epochs": 2, "tuner/initial_epoch": 0, "tuner/bracket": 4, "tuner/round": 0}}, "metrics": {"metrics": {}}, "score": null, "best_step": 0, "status": "FAILED", "message": "Traceback (most recent call last):\n  File \"C:\\Users\\cryst\\anaconda3\\lib\\site-packages\\keras_tuner\\engine\\base_tuner.py\", line 270, in _try_run_and_update_trial\n    self._run_and_update_trial(trial, *fit_args, **fit_kwargs)\n  File \"C:\\Users\\cryst\\anaconda3\\lib\\site-packages\\keras_tuner\\engine\\base_tuner.py\", line 235, in _run_and_update_trial\n    results = self.run_trial(trial, *fit_args, **fit_kwargs)\n  File \"C:\\Users\\cryst\\anaconda3\\lib\\site-packages\\keras_tuner\\tuners\\hyperband.py\", line 425, in run_trial\n    return super().run_trial(trial, *fit_args, **fit_kwargs)\n  File \"C:\\Users\\cryst\\anaconda3\\lib\\site-packages\\keras_tuner\\engine\\tuner.py\", line 287, in run_trial\n    obj_value = self._build_and_fit_model(trial, *args, **copied_kwargs)\n  File \"C:\\Users\\cryst\\anaconda3\\lib\\site-packages\\keras_tuner\\engine\\tuner.py\", line 214, in _build_and_fit_model\n    results = self.hypermodel.fit(hp, model, *args, **kwargs)\n  File \"C:\\Users\\cryst\\anaconda3\\lib\\site-packages\\keras_tuner\\engine\\hypermodel.py\", line 144, in fit\n    return model.fit(*args, **kwargs)\n  File \"C:\\Users\\cryst\\anaconda3\\lib\\site-packages\\keras\\utils\\traceback_utils.py\", line 70, in error_handler\n    raise e.with_traceback(filtered_tb) from None\n  File \"C:\\Users\\cryst\\AppData\\Local\\Temp\\__autograph_generated_fileui1lslpg.py\", line 15, in tf__train_function\n    retval_ = ag__.converted_call(ag__.ld(step_function), (ag__.ld(self), ag__.ld(iterator)), None, fscope)\nValueError: in user code:\n\n    File \"C:\\Users\\cryst\\anaconda3\\lib\\site-packages\\keras\\engine\\training.py\", line 1284, in train_function  *\n        return step_function(self, iterator)\n    File \"C:\\Users\\cryst\\anaconda3\\lib\\site-packages\\keras\\engine\\training.py\", line 1268, in step_function  **\n        outputs = model.distribute_strategy.run(run_step, args=(data,))\n    File \"C:\\Users\\cryst\\anaconda3\\lib\\site-packages\\keras\\engine\\training.py\", line 1249, in run_step  **\n        outputs = model.train_step(data)\n    File \"C:\\Users\\cryst\\anaconda3\\lib\\site-packages\\keras\\engine\\training.py\", line 1050, in train_step\n        y_pred = self(x, training=True)\n    File \"C:\\Users\\cryst\\anaconda3\\lib\\site-packages\\keras\\utils\\traceback_utils.py\", line 70, in error_handler\n        raise e.with_traceback(filtered_tb) from None\n    File \"C:\\Users\\cryst\\anaconda3\\lib\\site-packages\\keras\\engine\\input_spec.py\", line 298, in assert_input_compatibility\n        raise ValueError(\n\n    ValueError: Input 0 of layer \"sequential\" is incompatible with the layer: expected shape=(None, 2), found shape=(None, 40)\n\n"}